import {
  throwError,
  throwCustomError,
  resolveValue,
  MyAwesomeError,
  rejectCustomError,
} from './index';

describe('resolveValue', () => {
  test('should resolve provided value', async () => {
    const value = 42;
    const result = await resolveValue(value);
    expect(result).toBe(value);
  });
});

describe('throwError', () => {
  test('should throw error with provided message', () => {
    const errorMsg = 'Custom error message';
    expect(() => throwError(errorMsg)).toThrowError(errorMsg);
  });

  test('should throw error with default message if message is not provided', () => {
    expect(() => throwError()).toThrowError('Oops!');
  });
});

describe('throwCustomError', () => {
  test('should throw custom error', () => {
    expect(() => throwCustomError()).toThrowError(MyAwesomeError);
    expect(() => throwCustomError()).toThrowError(
      'This is my awesome custom error',
    );
  });
});

describe('rejectCustomError', () => {
  test('should reject custom error', async () => {
    await expect(rejectCustomError()).rejects.toThrowError(MyAwesomeError);
    await expect(rejectCustomError()).rejects.toThrowError(
      'This is my awesome custom error!',
    );
  });
});
